Workbook

Sheet Dashboard
A1: DSA PATTERNS MASTER TRACKER — Product-Based Company Prep
A2: Update Status in 'Problem Tracker' — everything here recalculates automatically.
D3: Bucket | E3: Total | F3: Solved | G3: % Done
A4: Total Problems | B4: =COUNTA('Problem Tracker'!$G$2:$G$541) -> 540 | D4: Easy | E4: =COUNTIF('Problem Tracker'!$H:$H,"Easy") -> 104 | F4: =(COUNTIFS('Problem Tracker'!$M:$M,"Solved",'Problem Tracker'!$H:$H,"Easy")+COUNTIFS('Problem Tracker'!$M:$M,"Mastered",'Problem Tracker'!$H:$H,"Easy")) -> 1 | G4: =IF(E4=0,0,F4/E4) -> 0.0096153846
A5: Solved / Mastered | B5: =(COUNTIFS('Problem Tracker'!$M:$M,"Solved")+COUNTIFS('Problem Tracker'!$M:$M,"Mastered")) -> 1 | D5: Medium | E5: =COUNTIF('Problem Tracker'!$H:$H,"Medium") -> 340 | F5: =(COUNTIFS('Problem Tracker'!$M:$M,"Solved",'Problem Tracker'!$H:$H,"Medium")+COUNTIFS('Problem Tracker'!$M:$M,"Mastered",'Problem Tracker'!$H:$H,"Medium")) -> 0 | G5: =IF(E5=0,0,F5/E5) -> 0
A6: Overall Progress | B6: =IF(B4=0,0,B5/B4) -> 0.0018518519 | D6: Hard | E6: =COUNTIF('Problem Tracker'!$H:$H,"Hard") -> 96 | F6: =(COUNTIFS('Problem Tracker'!$M:$M,"Solved",'Problem Tracker'!$H:$H,"Hard")+COUNTIFS('Problem Tracker'!$M:$M,"Mastered",'Problem Tracker'!$H:$H,"Hard")) -> 0 | G6: =IF(E6=0,0,F6/E6) -> 0
A7: Due for Revision Today | B7: =COUNTIFS('Problem Tracker'!$P$2:$P$541,"<="&TODAY(),'Problem Tracker'!$M$2:$M$541,"<>Mastered") -> 0 | D7: ★ Blind 75 | E7: =COUNTIF('Problem Tracker'!$I:$I,"★ Blind 75") -> 75 | F7: =(COUNTIFS('Problem Tracker'!$M:$M,"Solved",'Problem Tracker'!$I:$I,"★ Blind 75")+COUNTIFS('Problem Tracker'!$M:$M,"Mastered",'Problem Tracker'!$I:$I,"★ Blind 75")) -> 1 | G7: =IF(E7=0,0,F7/E7) -> 0.013333333
D8: ◆ NeetCode 150 (extra) | E8: =COUNTIF('Problem Tracker'!$I:$I,"◆ NeetCode 150") -> 76 | F8: =(COUNTIFS('Problem Tracker'!$M:$M,"Solved",'Problem Tracker'!$I:$I,"◆ NeetCode 150")+COUNTIFS('Problem Tracker'!$M:$M,"Mastered",'Problem Tracker'!$I:$I,"◆ NeetCode 150")) -> 0 | G8: =IF(E8=0,0,F8/E8) -> 0
D9: ● Must-Know Classic | E9: =COUNTIF('Problem Tracker'!$I:$I,"● Must-Know Classic") -> 84 | F9: =(COUNTIFS('Problem Tracker'!$M:$M,"Solved",'Problem Tracker'!$I:$I,"● Must-Know Classic")+COUNTIFS('Problem Tracker'!$M:$M,"Mastered",'Problem Tracker'!$I:$I,"● Must-Know Classic")) -> 0 | G9: =IF(E9=0,0,F9/E9) -> 0
D10: P0 + P1 (core set) | E10: =COUNTIF('Problem Tracker'!$J:$J,"P0")+COUNTIF('Problem Tracker'!$J:$J,"P1") -> 235 | F10: =(COUNTIFS('Problem Tracker'!$M:$M,"Solved",'Problem Tracker'!$J:$J,"P0")+COUNTIFS('Problem Tracker'!$M:$M,"Mastered",'Problem Tracker'!$J:$J,"P0"))+(COUNTIFS('Problem Tracker'!$M:$M,"Solved",'Problem Tracker'!$J:$J,"P1")+COUNTIFS('Problem Tracker'!$M:$M,"Mastered",'Problem Tracker'!$J:$J,"P1")) -> 1 | G10: =IF(E10=0,0,F10/E10) -> 0.0042553191
A12: PROGRESS BY DATA STRUCTURE
A13: Data Structure | B13: Week | C13: Total | D13: Easy | E13: Medium | F13: Hard | G13: ★ Blind 75 | H13: Solved | I13: % Done
A14: Hash Map & Set | B14: W01 | C14: =COUNTIFS('Problem Tracker'!$C:$C,"Hash Map & Set") -> 13 | D14: =COUNTIFS('Problem Tracker'!$C:$C,"Hash Map & Set",'Problem Tracker'!$H:$H,"Easy") -> 6 | E14: =COUNTIFS('Problem Tracker'!$C:$C,"Hash Map & Set",'Problem Tracker'!$H:$H,"Medium") -> 7 | F14: =COUNTIFS('Problem Tracker'!$C:$C,"Hash Map & Set",'Problem Tracker'!$H:$H,"Hard") -> 0 | G14: =COUNTIFS('Problem Tracker'!$C:$C,"Hash Map & Set",'Problem Tracker'!$I:$I,"★ Blind 75") -> 3 | H14: =(COUNTIFS('Problem Tracker'!$M:$M,"Solved",'Problem Tracker'!$C:$C,"Hash Map & Set")+COUNTIFS('Problem Tracker'!$M:$M,"Mastered",'Problem Tracker'!$C:$C,"Hash Map & Set")) -> 1 | I14: =IF(C14=0,0,H14/C14) -> 0.076923077
A15: Array | B15: W02–03 | C15: =COUNTIFS('Problem Tracker'!$C:$C,"Array") -> 74 | D15: =COUNTIFS('Problem Tracker'!$C:$C,"Array",'Problem Tracker'!$H:$H,"Easy") -> 15 | E15: =COUNTIFS('Problem Tracker'!$C:$C,"Array",'Problem Tracker'!$H:$H,"Medium") -> 49 | F15: =COUNTIFS('Problem Tracker'!$C:$C,"Array",'Problem Tracker'!$H:$H,"Hard") -> 10 | G15: =COUNTIFS('Problem Tracker'!$C:$C,"Array",'Problem Tracker'!$I:$I,"★ Blind 75") -> 10 | H15: =(COUNTIFS('Problem Tracker'!$M:$M,"Solved",'Problem Tracker'!$C:$C,"Array")+COUNTIFS('Problem Tracker'!$M:$M,"Mastered",'Problem Tracker'!$C:$C,"Array")) -> 0 | I15: =IF(C15=0,0,H15/C15) -> 0
A16: String | B16: W03 | C16: =COUNTIFS('Problem Tracker'!$C:$C,"String") -> 34 | D16: =COUNTIFS('Problem Tracker'!$C:$C,"String",'Problem Tracker'!$H:$H,"Easy") -> 13 | E16: =COUNTIFS('Problem Tracker'!$C:$C,"String",'Problem Tracker'!$H:$H,"Medium") -> 15 | F16: =COUNTIFS('Problem Tracker'!$C:$C,"String",'Problem Tracker'!$H:$H,"Hard") -> 6 | G16: =COUNTIFS('Problem Tracker'!$C:$C,"String",'Problem Tracker'!$I:$I,"★ Blind 75") -> 5 | H16: =(COUNTIFS('Problem Tracker'!$M:$M,"Solved",'Problem Tracker'!$C:$C,"String")+COUNTIFS('Problem Tracker'!$M:$M,"Mastered",'Problem Tracker'!$C:$C,"String")) -> 0 | I16: =IF(C16=0,0,H16/C16) -> 0
A17: Matrix (2D Array) | B17: W03 | C17: =COUNTIFS('Problem Tracker'!$C:$C,"Matrix (2D Array)") -> 8 | D17: =COUNTIFS('Problem Tracker'!$C:$C,"Matrix (2D Array)",'Problem Tracker'!$H:$H,"Easy") -> 2 | E17: =COUNTIFS('Problem Tracker'!$C:$C,"Matrix (2D Array)",'Problem Tracker'!$H:$H,"Medium") -> 6 | F17: =COUNTIFS('Problem Tracker'!$C:$C,"Matrix (2D Array)",'Problem Tracker'!$H:$H,"Hard") -> 0 | G17: =COUNTIFS('Problem Tracker'!$C:$C,"Matrix (2D Array)",'Problem Tracker'!$I:$I,"★ Blind 75") -> 3 | H17: =(COUNTIFS('Problem Tracker'!$M:$M,"Solved",'Problem Tracker'!$C:$C,"Matrix (2D Array)")+COUNTIFS('Problem Tracker'!$M:$M,"Mastered",'Problem Tracker'!$C:$C,"Matrix (2D Array)")) -> 0 | I17: =IF(C17=0,0,H17/C17) -> 0
A18: Stack | B18: W04 | C18: =COUNTIFS('Problem Tracker'!$C:$C,"Stack") -> 29 | D18: =COUNTIFS('Problem Tracker'!$C:$C,"Stack",'Problem Tracker'!$H:$H,"Easy") -> 5 | E18: =COUNTIFS('Problem Tracker'!$C:$C,"Stack",'Problem Tracker'!$H:$H,"Medium") -> 19 | F18: =COUNTIFS('Problem Tracker'!$C:$C,"Stack",'Problem Tracker'!$H:$H,"Hard") -> 5 | G18: =COUNTIFS('Problem Tracker'!$C:$C,"Stack",'Problem Tracker'!$I:$I,"★ Blind 75") -> 1 | H18: =(COUNTIFS('Problem Tracker'!$M:$M,"Solved",'Problem Tracker'!$C:$C,"Stack")+COUNTIFS('Problem Tracker'!$M:$M,"Mastered",'Problem Tracker'!$C:$C,"Stack")) -> 0 | I18: =IF(C18=0,0,H18/C18) -> 0
A19: Queue / Deque | B19: W04 | C19: =COUNTIFS('Problem Tracker'!$C:$C,"Queue / Deque") -> 5 | D19: =COUNTIFS('Problem Tracker'!$C:$C,"Queue / Deque",'Problem Tracker'!$H:$H,"Easy") -> 1 | E19: =COUNTIFS('Problem Tracker'!$C:$C,"Queue / Deque",'Problem Tracker'!$H:$H,"Medium") -> 4 | F19: =COUNTIFS('Problem Tracker'!$C:$C,"Queue / Deque",'Problem Tracker'!$H:$H,"Hard") -> 0 | G19: =COUNTIFS('Problem Tracker'!$C:$C,"Queue / Deque",'Problem Tracker'!$I:$I,"★ Blind 75") -> 0 | H19: =(COUNTIFS('Problem Tracker'!$M:$M,"Solved",'Problem Tracker'!$C:$C,"Queue / Deque")+COUNTIFS('Problem Tracker'!$M:$M,"Mastered",'Problem Tracker'!$C:$C,"Queue / Deque")) -> 0 | I19: =IF(C19=0,0,H19/C19) -> 0
A20: Binary Search | B20: W05 | C20: =COUNTIFS('Problem Tracker'!$C:$C,"Binary Search") -> 28 | D20: =COUNTIFS('Problem Tracker'!$C:$C,"Binary Search",'Problem Tracker'!$H:$H,"Easy") -> 5 | E20: =COUNTIFS('Problem Tracker'!$C:$C,"Binary Search",'Problem Tracker'!$H:$H,"Medium") -> 18 | F20: =COUNTIFS('Problem Tracker'!$C:$C,"Binary Search",'Problem Tracker'!$H:$H,"Hard") -> 5 | G20: =COUNTIFS('Problem Tracker'!$C:$C,"Binary Search",'Problem Tracker'!$I:$I,"★ Blind 75") -> 2 | H20: =(COUNTIFS('Problem Tracker'!$M:$M,"Solved",'Problem Tracker'!$C:$C,"Binary Search")+COUNTIFS('Problem Tracker'!$M:$M,"Mastered",'Problem Tracker'!$C:$C,"Binary Search")) -> 0 | I20: =IF(C20=0,0,H20/C20) -> 0
A21: Linked List | B21: W06 | C21: =COUNTIFS('Problem Tracker'!$C:$C,"Linked List") -> 25 | D21: =COUNTIFS('Problem Tracker'!$C:$C,"Linked List",'Problem Tracker'!$H:$H,"Easy") -> 8 | E21: =COUNTIFS('Problem Tracker'!$C:$C,"Linked List",'Problem Tracker'!$H:$H,"Medium") -> 16 | F21: =COUNTIFS('Problem Tracker'!$C:$C,"Linked List",'Problem Tracker'!$H:$H,"Hard") -> 1 | G21: =COUNTIFS('Problem Tracker'!$C:$C,"Linked List",'Problem Tracker'!$I:$I,"★ Blind 75") -> 5 | H21: =(COUNTIFS('Problem Tracker'!$M:$M,"Solved",'Problem Tracker'!$C:$C,"Linked List")+COUNTIFS('Problem Tracker'!$M:$M,"Mastered",'Problem Tracker'!$C:$C,"Linked List")) -> 0 | I21: =IF(C21=0,0,H21/C21) -> 0
A22: Intervals | B22: W06 | C22: =COUNTIFS('Problem Tracker'!$C:$C,"Intervals") -> 14 | D22: =COUNTIFS('Problem Tracker'!$C:$C,"Intervals",'Problem Tracker'!$H:$H,"Easy") -> 2 | E22: =COUNTIFS('Problem Tracker'!$C:$C,"Intervals",'Problem Tracker'!$H:$H,"Medium") -> 7 | F22: =COUNTIFS('Problem Tracker'!$C:$C,"Intervals",'Problem Tracker'!$H:$H,"Hard") -> 5 | G22: =COUNTIFS('Problem Tracker'!$C:$C,"Intervals",'Problem Tracker'!$I:$I,"★ Blind 75") -> 5 | H22: =(COUNTIFS('Problem Tracker'!$M:$M,"Solved",'Problem Tracker'!$C:$C,"Intervals")+COUNTIFS('Problem Tracker'!$M:$M,"Mastered",'Problem Tracker'!$C:$C,"Intervals")) -> 0 | I22: =IF(C22=0,0,H22/C22) -> 0
A23: Trees | B23: W07–08 | C23: =COUNTIFS('Problem Tracker'!$C:$C,"Trees") -> 50 | D23: =COUNTIFS('Problem Tracker'!$C:$C,"Trees",'Problem Tracker'!$H:$H,"Easy") -> 19 | E23: =COUNTIFS('Problem Tracker'!$C:$C,"Trees",'Problem Tracker'!$H:$H,"Medium") -> 28 | F23: =COUNTIFS('Problem Tracker'!$C:$C,"Trees",'Problem Tracker'!$H:$H,"Hard") -> 3 | G23: =COUNTIFS('Problem Tracker'!$C:$C,"Trees",'Problem Tracker'!$I:$I,"★ Blind 75") -> 11 | H23: =(COUNTIFS('Problem Tracker'!$M:$M,"Solved",'Problem Tracker'!$C:$C,"Trees")+COUNTIFS('Problem Tracker'!$M:$M,"Mastered",'Problem Tracker'!$C:$C,"Trees")) -> 0 | I23: =IF(C23=0,0,H23/C23) -> 0
A24: Heap / Priority Queue | B24: W09 | C24: =COUNTIFS('Problem Tracker'!$C:$C,"Heap / Priority Queue") -> 19 | D24: =COUNTIFS('Problem Tracker'!$C:$C,"Heap / Priority Queue",'Problem Tracker'!$H:$H,"Easy") -> 2 | E24: =COUNTIFS('Problem Tracker'!$C:$C,"Heap / Priority Queue",'Problem Tracker'!$H:$H,"Medium") -> 10 | F24: =COUNTIFS('Problem Tracker'!$C:$C,"Heap / Priority Queue",'Problem Tracker'!$H:$H,"Hard") -> 7 | G24: =COUNTIFS('Problem Tracker'!$C:$C,"Heap / Priority Queue",'Problem Tracker'!$I:$I,"★ Blind 75") -> 3 | H24: =(COUNTIFS('Problem Tracker'!$M:$M,"Solved",'Problem Tracker'!$C:$C,"Heap / Priority Queue")+COUNTIFS('Problem Tracker'!$M:$M,"Mastered",'Problem Tracker'!$C:$C,"Heap / Priority Queue")) -> 0 | I24: =IF(C24=0,0,H24/C24) -> 0
A25: Recursion & Backtracking | B25: W10 | C25: =COUNTIFS('Problem Tracker'!$C:$C,"Recursion & Backtracking") -> 27 | D25: =COUNTIFS('Problem Tracker'!$C:$C,"Recursion & Backtracking",'Problem Tracker'!$H:$H,"Easy") -> 1 | E25: =COUNTIFS('Problem Tracker'!$C:$C,"Recursion & Backtracking",'Problem Tracker'!$H:$H,"Medium") -> 20 | F25: =COUNTIFS('Problem Tracker'!$C:$C,"Recursion & Backtracking",'Problem Tracker'!$H:$H,"Hard") -> 6 | G25: =COUNTIFS('Problem Tracker'!$C:$C,"Recursion & Backtracking",'Problem Tracker'!$I:$I,"★ Blind 75") -> 1 | H25: =(COUNTIFS('Problem Tracker'!$M:$M,"Solved",'Problem Tracker'!$C:$C,"Recursion & Backtracking")+COUNTIFS('Problem Tracker'!$M:$M,"Mastered",'Problem Tracker'!$C:$C,"Recursion & Backtracking")) -> 0 | I25: =IF(C25=0,0,H25/C25) -> 0
A26: Trie | B26: W10 | C26: =COUNTIFS('Problem Tracker'!$C:$C,"Trie") -> 10 | D26: =COUNTIFS('Problem Tracker'!$C:$C,"Trie",'Problem Tracker'!$H:$H,"Easy") -> 0 | E26: =COUNTIFS('Problem Tracker'!$C:$C,"Trie",'Problem Tracker'!$H:$H,"Medium") -> 7 | F26: =COUNTIFS('Problem Tracker'!$C:$C,"Trie",'Problem Tracker'!$H:$H,"Hard") -> 3 | G26: =COUNTIFS('Problem Tracker'!$C:$C,"Trie",'Problem Tracker'!$I:$I,"★ Blind 75") -> 3 | H26: =(COUNTIFS('Problem Tracker'!$M:$M,"Solved",'Problem Tracker'!$C:$C,"Trie")+COUNTIFS('Problem Tracker'!$M:$M,"Mastered",'Problem Tracker'!$C:$C,"Trie")) -> 0 | I26: =IF(C26=0,0,H26/C26) -> 0
A27: Graphs | B27: W11–12 | C27: =COUNTIFS('Problem Tracker'!$C:$C,"Graphs") -> 57 | D27: =COUNTIFS('Problem Tracker'!$C:$C,"Graphs",'Problem Tracker'!$H:$H,"Easy") -> 4 | E27: =COUNTIFS('Problem Tracker'!$C:$C,"Graphs",'Problem Tracker'!$H:$H,"Medium") -> 43 | F27: =COUNTIFS('Problem Tracker'!$C:$C,"Graphs",'Problem Tracker'!$H:$H,"Hard") -> 10 | G27: =COUNTIFS('Problem Tracker'!$C:$C,"Graphs",'Problem Tracker'!$I:$I,"★ Blind 75") -> 7 | H27: =(COUNTIFS('Problem Tracker'!$M:$M,"Solved",'Problem Tracker'!$C:$C,"Graphs")+COUNTIFS('Problem Tracker'!$M:$M,"Mastered",'Problem Tracker'!$C:$C,"Graphs")) -> 0 | I27: =IF(C27=0,0,H27/C27) -> 0
A28: Greedy | B28: W13 | C28: =COUNTIFS('Problem Tracker'!$C:$C,"Greedy") -> 15 | D28: =COUNTIFS('Problem Tracker'!$C:$C,"Greedy",'Problem Tracker'!$H:$H,"Easy") -> 3 | E28: =COUNTIFS('Problem Tracker'!$C:$C,"Greedy",'Problem Tracker'!$H:$H,"Medium") -> 10 | F28: =COUNTIFS('Problem Tracker'!$C:$C,"Greedy",'Problem Tracker'!$H:$H,"Hard") -> 2 | G28: =COUNTIFS('Problem Tracker'!$C:$C,"Greedy",'Problem Tracker'!$I:$I,"★ Blind 75") -> 1 | H28: =(COUNTIFS('Problem Tracker'!$M:$M,"Solved",'Problem Tracker'!$C:$C,"Greedy")+COUNTIFS('Problem Tracker'!$M:$M,"Mastered",'Problem Tracker'!$C:$C,"Greedy")) -> 0 | I28: =IF(C28=0,0,H28/C28) -> 0
A29: Bit Manipulation | B29: W13 | C29: =COUNTIFS('Problem Tracker'!$C:$C,"Bit Manipulation") -> 15 | D29: =COUNTIFS('Problem Tracker'!$C:$C,"Bit Manipulation",'Problem Tracker'!$H:$H,"Easy") -> 7 | E29: =COUNTIFS('Problem Tracker'!$C:$C,"Bit Manipulation",'Problem Tracker'!$H:$H,"Medium") -> 8 | F29: =COUNTIFS('Problem Tracker'!$C:$C,"Bit Manipulation",'Problem Tracker'!$H:$H,"Hard") -> 0 | G29: =COUNTIFS('Problem Tracker'!$C:$C,"Bit Manipulation",'Problem Tracker'!$I:$I,"★ Blind 75") -> 5 | H29: =(COUNTIFS('Problem Tracker'!$M:$M,"Solved",'Problem Tracker'!$C:$C,"Bit Manipulation")+COUNTIFS('Problem Tracker'!$M:$M,"Mastered",'Problem Tracker'!$C:$C,"Bit Manipulation")) -> 0 | I29: =IF(C29=0,0,H29/C29) -> 0
A30: Dynamic Programming | B30: W14–16 | C30: =COUNTIFS('Problem Tracker'!$C:$C,"Dynamic Programming") -> 71 | D30: =COUNTIFS('Problem Tracker'!$C:$C,"Dynamic Programming",'Problem Tracker'!$H:$H,"Easy") -> 3 | E30: =COUNTIFS('Problem Tracker'!$C:$C,"Dynamic Programming",'Problem Tracker'!$H:$H,"Medium") -> 47 | F30: =COUNTIFS('Problem Tracker'!$C:$C,"Dynamic Programming",'Problem Tracker'!$H:$H,"Hard") -> 21 | G30: =COUNTIFS('Problem Tracker'!$C:$C,"Dynamic Programming",'Problem Tracker'!$I:$I,"★ Blind 75") -> 10 | H30: =(COUNTIFS('Problem Tracker'!$M:$M,"Solved",'Problem Tracker'!$C:$C,"Dynamic Programming")+COUNTIFS('Problem Tracker'!$M:$M,"Mastered",'Problem Tracker'!$C:$C,"Dynamic Programming")) -> 0 | I30: =IF(C30=0,0,H30/C30) -> 0
A31: Sorting | B31: W16 | C31: =COUNTIFS('Problem Tracker'!$C:$C,"Sorting") -> 12 | D31: =COUNTIFS('Problem Tracker'!$C:$C,"Sorting",'Problem Tracker'!$H:$H,"Easy") -> 2 | E31: =COUNTIFS('Problem Tracker'!$C:$C,"Sorting",'Problem Tracker'!$H:$H,"Medium") -> 7 | F31: =COUNTIFS('Problem Tracker'!$C:$C,"Sorting",'Problem Tracker'!$H:$H,"Hard") -> 3 | G31: =COUNTIFS('Problem Tracker'!$C:$C,"Sorting",'Problem Tracker'!$I:$I,"★ Blind 75") -> 0 | H31: =(COUNTIFS('Problem Tracker'!$M:$M,"Solved",'Problem Tracker'!$C:$C,"Sorting")+COUNTIFS('Problem Tracker'!$M:$M,"Mastered",'Problem Tracker'!$C:$C,"Sorting")) -> 0 | I31: =IF(C31=0,0,H31/C31) -> 0
A32: Math & Geometry | B32: W16 | C32: =COUNTIFS('Problem Tracker'!$C:$C,"Math & Geometry") -> 13 | D32: =COUNTIFS('Problem Tracker'!$C:$C,"Math & Geometry",'Problem Tracker'!$H:$H,"Easy") -> 4 | E32: =COUNTIFS('Problem Tracker'!$C:$C,"Math & Geometry",'Problem Tracker'!$H:$H,"Medium") -> 8 | F32: =COUNTIFS('Problem Tracker'!$C:$C,"Math & Geometry",'Problem Tracker'!$H:$H,"Hard") -> 1 | G32: =COUNTIFS('Problem Tracker'!$C:$C,"Math & Geometry",'Problem Tracker'!$I:$I,"★ Blind 75") -> 0 | H32: =(COUNTIFS('Problem Tracker'!$M:$M,"Solved",'Problem Tracker'!$C:$C,"Math & Geometry")+COUNTIFS('Problem Tracker'!$M:$M,"Mastered",'Problem Tracker'!$C:$C,"Math & Geometry")) -> 0 | I32: =IF(C32=0,0,H32/C32) -> 0
A33: Design | B33: W17 | C33: =COUNTIFS('Problem Tracker'!$C:$C,"Design") -> 14 | D33: =COUNTIFS('Problem Tracker'!$C:$C,"Design",'Problem Tracker'!$H:$H,"Easy") -> 2 | E33: =COUNTIFS('Problem Tracker'!$C:$C,"Design",'Problem Tracker'!$H:$H,"Medium") -> 9 | F33: =COUNTIFS('Problem Tracker'!$C:$C,"Design",'Problem Tracker'!$H:$H,"Hard") -> 3 | G33: =COUNTIFS('Problem Tracker'!$C:$C,"Design",'Problem Tracker'!$I:$I,"★ Blind 75") -> 0 | H33: =(COUNTIFS('Problem Tracker'!$M:$M,"Solved",'Problem Tracker'!$C:$C,"Design")+COUNTIFS('Problem Tracker'!$M:$M,"Mastered",'Problem Tracker'!$C:$C,"Design")) -> 0 | I33: =IF(C33=0,0,H33/C33) -> 0
A34: Advanced Data Structures | B34: W17 | C34: =COUNTIFS('Problem Tracker'!$C:$C,"Advanced Data Structures") -> 7 | D34: =COUNTIFS('Problem Tracker'!$C:$C,"Advanced Data Structures",'Problem Tracker'!$H:$H,"Easy") -> 0 | E34: =COUNTIFS('Problem Tracker'!$C:$C,"Advanced Data Structures",'Problem Tracker'!$H:$H,"Medium") -> 2 | F34: =COUNTIFS('Problem Tracker'!$C:$C,"Advanced Data Structures",'Problem Tracker'!$H:$H,"Hard") -> 5 | G34: =COUNTIFS('Problem Tracker'!$C:$C,"Advanced Data Structures",'Problem Tracker'!$I:$I,"★ Blind 75") -> 0 | H34: =(COUNTIFS('Problem Tracker'!$M:$M,"Solved",'Problem Tracker'!$C:$C,"Advanced Data Structures")+COUNTIFS('Problem Tracker'!$M:$M,"Mastered",'Problem Tracker'!$C:$C,"Advanced Data Structures")) -> 0 | I34: =IF(C34=0,0,H34/C34) -> 0
A35: TOTAL | C35: =SUM(C14:C34) -> 540 | D35: =SUM(D14:D34) -> 104 | E35: =SUM(E14:E34) -> 340 | F35: =SUM(F14:F34) -> 96 | G35: =SUM(G14:G34) -> 75 | H35: =SUM(H14:H34) -> 1 | I35: =IF(C35=0,0,H35/C35) -> 0.0018518519
A37: 17-WEEK STUDY PLAN
A38: Week | B38: Focus | F38: Problems | G38: Solved | H38: % Done
A39: W01 | B39: Hash Map & Set: Hashing Fundamentals | F39: =COUNTIF('Problem Tracker'!$B:$B,A39) -> 13 | G39: =COUNTIFS('Problem Tracker'!$B:$B,A39,'Problem Tracker'!$M:$M,"Solved")+COUNTIFS('Problem Tracker'!$B:$B,A39,'Problem Tracker'!$M:$M,"Mastered") -> 1 | H39: =IF(F39=0,0,G39/F39) -> 0.076923077
A40: W02 | B40: Array: Two Pointers; Array: In-place Manipulation | F40: =COUNTIF('Problem Tracker'!$B:$B,A40) -> 27 | G40: =COUNTIFS('Problem Tracker'!$B:$B,A40,'Problem Tracker'!$M:$M,"Solved")+COUNTIFS('Problem Tracker'!$B:$B,A40,'Problem Tracker'!$M:$M,"Mastered") -> 0 | H40: =IF(F40=0,0,G40/F40) -> 0
A41: W03 | B41: Array: Sliding Window; Array: Prefix Sum; Array: Kadane's / Subarray; String: Palindrome; String: Anagram / Frequency; String: Pattern Matching; String: Parsing & Simulation; Matrix (2D Array): Matrix Manipulation | F41: =COUNTIF('Problem Tracker'!$B:$B,A41) -> 89 | G41: =COUNTIFS('Problem Tracker'!$B:$B,A41,'Problem Tracker'!$M:$M,"Solved")+COUNTIFS('Problem Tracker'!$B:$B,A41,'Problem Tracker'!$M:$M,"Mastered") -> 0 | H41: =IF(F41=0,0,G41/F41) -> 0
A42: W04 | B42: Stack: Classic Stack; Stack: Monotonic Stack; Stack: Stack Design; Queue / Deque: Queue Patterns | F42: =COUNTIF('Problem Tracker'!$B:$B,A42) -> 34 | G42: =COUNTIFS('Problem Tracker'!$B:$B,A42,'Problem Tracker'!$M:$M,"Solved")+COUNTIFS('Problem Tracker'!$B:$B,A42,'Problem Tracker'!$M:$M,"Mastered") -> 0 | H42: =IF(F42=0,0,G42/F42) -> 0
...

Sheet Pattern Map
A1: Data Structure | B1: Pattern | C1: Sub-Pattern | D1: Interview Weight | E1: How to Recognize (Trigger) | F1: Core Technique / Template | G1: Complexity | H1: Week | I1: Problems | J1: Easy | K1: Medium | L1: Hard | M1: Solved | N1: % Done
A2: ▌ HASH MAP & SET | I2: =COUNTIF('Problem Tracker'!$C:$C,"Hash Map & Set") -> 13 | M2: =COUNTIFS('Problem Tracker'!$C:$C,"Hash Map & Set",'Problem Tracker'!$M:$M,"Solved")+COUNTIFS('Problem Tracker'!$C:$C,"Hash Map & Set",'Problem Tracker'!$M:$M,"Mastered") -> 1 | N2: =IF(I2=0,0,M2/I2) -> 0.076923077
A3: Hash Map & Set | B3: Hashing Fundamentals | C3: Complement Lookup | D3: 🔥 Very High | E3: Find a pair/tuple summing to target in unsorted data | F3: Store value→index; for each x check target−x in map | G3: O(n) time, O(n) space | H3: W01 | I3: =COUNTIFS('Problem Tracker'!$C:$C,"Hash Map & Set",'Problem Tracker'!$D:$D,"Hashing Fundamentals",'Problem Tracker'!$E:$E,"Complement Lookup") -> 3 | J3: =COUNTIFS('Problem Tracker'!$C:$C,"Hash Map & Set",'Problem Tracker'!$D:$D,"Hashing Fundamentals",'Problem Tracker'!$E:$E,"Complement Lookup",'Problem Tracker'!$H:$H,"Easy") -> 1 | K3: =COUNTIFS('Problem Tracker'!$C:$C,"Hash Map & Set",'Problem Tracker'!$D:$D,"Hashing Fundamentals",'Problem Tracker'!$E:$E,"Complement Lookup",'Problem Tracker'!$H:$H,"Medium") -> 2 | L3: =COUNTIFS('Problem Tracker'!$C:$C,"Hash Map & Set",'Problem Tracker'!$D:$D,"Hashing Fundamentals",'Problem Tracker'!$E:$E,"Complement Lookup",'Problem Tracker'!$H:$H,"Hard") -> 0 | M3: =COUNTIFS('Problem Tracker'!$C:$C,"Hash Map & Set",'Problem Tracker'!$D:$D,"Hashing Fundamentals",'Problem Tracker'!$E:$E,"Complement Lookup",'Problem Tracker'!$M:$M,"Solved")+COUNTIFS('Problem Tracker'!$C:$C,"Hash Map & Set",'Problem Tracker'!$D:$D,"Hashing Fundamentals",'Problem Tracker'!$E:$E,"Complement Lookup",'Problem Tracker'!$M:$M,"Mastered") -> 1 | N3: =IF(I3=0,0,M3/I3) -> 0.33333333
A4: Hash Map & Set | B4: Hashing Fundamentals | C4: Frequency Counting | D4: 🔥 Very High | E4: Counts, duplicates, 'appears k times', compare multisets | F4: Counter / int[26] array; compare or scan counts | G4: O(n) | H4: W01 | I4: =COUNTIFS('Problem Tracker'!$C:$C,"Hash Map & Set",'Problem Tracker'!$D:$D,"Hashing Fundamentals",'Problem Tracker'!$E:$E,"Frequency Counting") -> 4 | J4: =COUNTIFS('Problem Tracker'!$C:$C,"Hash Map & Set",'Problem Tracker'!$D:$D,"Hashing Fundamentals",'Problem Tracker'!$E:$E,"Frequency Counting",'Problem Tracker'!$H:$H,"Easy") -> 3 | K4: =COUNTIFS('Problem Tracker'!$C:$C,"Hash Map & Set",'Problem Tracker'!$D:$D,"Hashing Fundamentals",'Problem Tracker'!$E:$E,"Frequency Counting",'Problem Tracker'!$H:$H,"Medium") -> 1 | L4: =COUNTIFS('Problem Tracker'!$C:$C,"Hash Map & Set",'Problem Tracker'!$D:$D,"Hashing Fundamentals",'Problem Tracker'!$E:$E,"Frequency Counting",'Problem Tracker'!$H:$H,"Hard") -> 0 | M4: =COUNTIFS('Problem Tracker'!$C:$C,"Hash Map & Set",'Problem Tracker'!$D:$D,"Hashing Fundamentals",'Problem Tracker'!$E:$E,"Frequency Counting",'Problem Tracker'!$M:$M,"Solved")+COUNTIFS('Problem Tracker'!$C:$C,"Hash Map & Set",'Problem Tracker'!$D:$D,"Hashing Fundamentals",'Problem Tracker'!$E:$E,"Frequency Counting",'Problem Tracker'!$M:$M,"Mastered") -> 0 | N4: =IF(I4=0,0,M4/I4) -> 0
A5: Hash Map & Set | B5: Hashing Fundamentals | C5: Grouping by Canonical Key | D5: High | E5: Group items that are 'equivalent' (anagrams, shifts, same content) | F5: Compute a canonical key (sorted string / count tuple) → list | G5: O(n·k) | H5: W01 | I5: =COUNTIFS('Problem Tracker'!$C:$C,"Hash Map & Set",'Problem Tracker'!$D:$D,"Hashing Fundamentals",'Problem Tracker'!$E:$E,"Grouping by Canonical Key") -> 3 | J5: =COUNTIFS('Problem Tracker'!$C:$C,"Hash Map & Set",'Problem Tracker'!$D:$D,"Hashing Fundamentals",'Problem Tracker'!$E:$E,"Grouping by Canonical Key",'Problem Tracker'!$H:$H,"Easy") -> 0 | K5: =COUNTIFS('Problem Tracker'!$C:$C,"Hash Map & Set",'Problem Tracker'!$D:$D,"Hashing Fundamentals",'Problem Tracker'!$E:$E,"Grouping by Canonical Key",'Problem Tracker'!$H:$H,"Medium") -> 3 | L5: =COUNTIFS('Problem Tracker'!$C:$C,"Hash Map & Set",'Problem Tracker'!$D:$D,"Hashing Fundamentals",'Problem Tracker'!$E:$E,"Grouping by Canonical Key",'Problem Tracker'!$H:$H,"Hard") -> 0 | M5: =COUNTIFS('Problem Tracker'!$C:$C,"Hash Map & Set",'Problem Tracker'!$D:$D,"Hashing Fundamentals",'Problem Tracker'!$E:$E,"Grouping by Canonical Key",'Problem Tracker'!$M:$M,"Solved")+COUNTIFS('Problem Tracker'!$C:$C,"Hash Map & Set",'Problem Tracker'!$D:$D,"Hashing Fundamentals",'Problem Tracker'!$E:$E,"Grouping by Canonical Key",'Problem Tracker'!$M:$M,"Mastered") -> 0 | N5: =IF(I5=0,0,M5/I5) -> 0
A6: Hash Map & Set | B6: Hashing Fundamentals | C6: Set Existence / Sequence Building | D6: 🔥 Very High | E6: Membership checks, consecutive runs, cycle detection on values | F6: HashSet; only start counting from sequence starts | G6: O(n) | H6: W01 | I6: =COUNTIFS('Problem Tracker'!$C:$C,"Hash Map & Set",'Problem Tracker'!$D:$D,"Hashing Fundamentals",'Problem Tracker'!$E:$E,"Set Existence / Sequence Building") -> 3 | J6: =COUNTIFS('Problem Tracker'!$C:$C,"Hash Map & Set",'Problem Tracker'!$D:$D,"Hashing Fundamentals",'Problem Tracker'!$E:$E,"Set Existence / Sequence Building",'Problem Tracker'!$H:$H,"Easy") -> 2 | K6: =COUNTIFS('Problem Tracker'!$C:$C,"Hash Map & Set",'Problem Tracker'!$D:$D,"Hashing Fundamentals",'Problem Tracker'!$E:$E,"Set Existence / Sequence Building",'Problem Tracker'!$H:$H,"Medium") -> 1 | L6: =COUNTIFS('Problem Tracker'!$C:$C,"Hash Map & Set",'Problem Tracker'!$D:$D,"Hashing Fundamentals",'Problem Tracker'!$E:$E,"Set Existence / Sequence Building",'Problem Tracker'!$H:$H,"Hard") -> 0 | M6: =COUNTIFS('Problem Tracker'!$C:$C,"Hash Map & Set",'Problem Tracker'!$D:$D,"Hashing Fundamentals",'Problem Tracker'!$E:$E,"Set Existence / Sequence Building",'Problem Tracker'!$M:$M,"Solved")+COUNTIFS('Problem Tracker'!$C:$C,"Hash Map & Set",'Problem Tracker'!$D:$D,"Hashing Fundamentals",'Problem Tracker'!$E:$E,"Set Existence / Sequence Building",'Problem Tracker'!$M:$M,"Mastered") -> 0 | N6: =IF(I6=0,0,M6/I6) -> 0
A7: ▌ ARRAY | I7: =COUNTIF('Problem Tracker'!$C:$C,"Array") -> 74 | M7: =COUNTIFS('Problem Tracker'!$C:$C,"Array",'Problem Tracker'!$M:$M,"Solved")+COUNTIFS('Problem Tracker'!$C:$C,"Array",'Problem Tracker'!$M:$M,"Mastered") -> 0 | N7: =IF(I7=0,0,M7/I7) -> 0
A8: Array | B8: Two Pointers | C8: Opposite Ends (Converging) | D8: 🔥 Very High | E8: Sorted array / palindrome / pair with target / maximize area | F8: l=0, r=n−1; move the pointer that can improve the answer | G8: O(n) | H8: W02 | I8: =COUNTIFS('Problem Tracker'!$C:$C,"Array",'Problem Tracker'!$D:$D,"Two Pointers",'Problem Tracker'!$E:$E,"Opposite Ends (Converging)") -> 6 | J8: =COUNTIFS('Problem Tracker'!$C:$C,"Array",'Problem Tracker'!$D:$D,"Two Pointers",'Problem Tracker'!$E:$E,"Opposite Ends (Converging)",'Problem Tracker'!$H:$H,"Easy") -> 2 | K8: =COUNTIFS('Problem Tracker'!$C:$C,"Array",'Problem Tracker'!$D:$D,"Two Pointers",'Problem Tracker'!$E:$E,"Opposite Ends (Converging)",'Problem Tracker'!$H:$H,"Medium") -> 3 | L8: =COUNTIFS('Problem Tracker'!$C:$C,"Array",'Problem Tracker'!$D:$D,"Two Pointers",'Problem Tracker'!$E:$E,"Opposite Ends (Converging)",'Problem Tracker'!$H:$H,"Hard") -> 1 | M8: =COUNTIFS('Problem Tracker'!$C:$C,"Array",'Problem Tracker'!$D:$D,"Two Pointers",'Problem Tracker'!$E:$E,"Opposite Ends (Converging)",'Problem Tracker'!$M:$M,"Solved")+COUNTIFS('Problem Tracker'!$C:$C,"Array",'Problem Tracker'!$D:$D,"Two Pointers",'Problem Tracker'!$E:$E,"Opposite Ends (Converging)",'Problem Tracker'!$M:$M,"Mastered") -> 0 | N8: =IF(I8=0,0,M8/I8) -> 0
A9: Array | B9: Two Pointers | C9: Same Direction (Read / Write) | D9: 🔥 Very High | E9: In-place remove/compact/merge; 'without extra space' | F9: Slow write pointer, fast read pointer | G9: O(n), O(1) space | H9: W02 | I9: =COUNTIFS('Problem Tracker'!$C:$C,"Array",'Problem Tracker'!$D:$D,"Two Pointers",'Problem Tracker'!$E:$E,"Same Direction (Read / Write)") -> 6 | J9: =COUNTIFS('Problem Tracker'!$C:$C,"Array",'Problem Tracker'!$D:$D,"Two Pointers",'Problem Tracker'!$E:$E,"Same Direction (Read / Write)",'Problem Tracker'!$H:$H,"Easy") -> 5 | K9: =COUNTIFS('Problem Tracker'!$C:$C,"Array",'Problem Tracker'!$D:$D,"Two Pointers",'Problem Tracker'!$E:$E,"Same Direction (Read / Write)",'Problem Tracker'!$H:$H,"Medium") -> 1 | L9: =COUNTIFS('Problem Tracker'!$C:$C,"Array",'Problem Tracker'!$D:$D,"Two Pointers",'Problem Tracker'!$E:$E,"Same Direction (Read / Write)",'Problem Tracker'!$H:$H,"Hard") -> 0 | M9: =COUNTIFS('Problem Tracker'!$C:$C,"Array",'Problem Tracker'!$D:$D,"Two Pointers",'Problem Tracker'!$E:$E,"Same Direction (Read / Write)",'Problem Tracker'!$M:$M,"Solved")+COUNTIFS('Problem Tracker'!$C:$C,"Array",'Problem Tracker'!$D:$D,"Two Pointers",'Problem Tracker'!$E:$E,"Same Direction (Read / Write)",'Problem Tracker'!$M:$M,"Mastered") -> 0 | N9: =IF(I9=0,0,M9/I9) -> 0
A10: Array | B10: Two Pointers | C10: k-Sum (3Sum / 4Sum) | D10: 🔥 Very High | E10: Find triplets/quads with target sum, avoid duplicates | F10: Sort; fix i, run two-pointer on rest; skip equal neighbours | G10: O(n^(k−1)) | H10: W02 | I10: =COUNTIFS('Problem Tracker'!$C:$C,"Array",'Problem Tracker'!$D:$D,"Two Pointers",'Problem Tracker'!$E:$E,"k-Sum (3Sum / 4Sum)") -> 4 | J10: =COUNTIFS('Problem Tracker'!$C:$C,"Array",'Problem Tracker'!$D:$D,"Two Pointers",'Problem Tracker'!$E:$E,"k-Sum (3Sum / 4Sum)",'Problem Tracker'!$H:$H,"Easy") -> 0 | K10: =COUNTIFS('Problem Tracker'!$C:$C,"Array",'Problem Tracker'!$D:$D,"Two Pointers",'Problem Tracker'!$E:$E,"k-Sum (3Sum / 4Sum)",'Problem Tracker'!$H:$H,"Medium") -> 4 | L10: =COUNTIFS('Problem Tracker'!$C:$C,"Array",'Problem Tracker'!$D:$D,"Two Pointers",'Problem Tracker'!$E:$E,"k-Sum (3Sum / 4Sum)",'Problem Tracker'!$H:$H,"Hard") -> 0 | M10: =COUNTIFS('Problem Tracker'!$C:$C,"Array",'Problem Tracker'!$D:$D,"Two Pointers",'Problem Tracker'!$E:$E,"k-Sum (3Sum / 4Sum)",'Problem Tracker'!$M:$M,"Solved")+COUNTIFS('Problem Tracker'!$C:$C,"Array",'Problem Tracker'!$D:$D,"Two Pointers",'Problem Tracker'!$E:$E,"k-Sum (3Sum / 4Sum)",'Problem Tracker'!$M:$M,"Mastered") -> 0 | N10: =IF(I10=0,0,M10/I10) -> 0
A11: Array | B11: Two Pointers | C11: Dutch National Flag / Partitioning | D11: High | E11: Sort 0/1/2 or partition around a pivot in one pass | F11: low / mid / high pointers; swap into regions | G11: O(n), O(1) | H11: W02 | I11: =COUNTIFS('Problem Tracker'!$C:$C,"Array",'Problem Tracker'!$D:$D,"Two Pointers",'Problem Tracker'!$E:$E,"Dutch National Flag / Partitioning") -> 3 | J11: =COUNTIFS('Problem Tracker'!$C:$C,"Array",'Problem Tracker'!$D:$D,"Two Pointers",'Problem Tracker'!$E:$E,"Dutch National Flag / Partitioning",'Problem Tracker'!$H:$H,"Easy") -> 1 | K11: =COUNTIFS('Problem Tracker'!$C:$C,"Array",'Problem Tracker'!$D:$D,"Two Pointers",'Problem Tracker'!$E:$E,"Dutch National Flag / Partitioning",'Problem Tracker'!$H:$H,"Medium") -> 2 | L11: =COUNTIFS('Problem Tracker'!$C:$C,"Array",'Problem Tracker'!$D:$D,"Two Pointers",'Problem Tracker'!$E:$E,"Dutch National Flag / Partitioning",'Problem Tracker'!$H:$H,"Hard") -> 0 | M11: =COUNTIFS('Problem Tracker'!$C:$C,"Array",'Problem Tracker'!$D:$D,"Two Pointers",'Problem Tracker'!$E:$E,"Dutch National Flag / Partitioning",'Problem Tracker'!$M:$M,"Solved")+COUNTIFS('Problem Tracker'!$C:$C,"Array",'Problem Tracker'!$D:$D,"Two Pointers",'Problem Tracker'!$E:$E,"Dutch National Flag / Partitioning",'Problem Tracker'!$M:$M,"Mastered") -> 0 | N11: =IF(I11=0,0,M11/I11) -> 0
A12: Array | B12: In-place Manipulation | C12: Rotation / Reversal Trick | D12: High | E12: Rotate by k, reverse segments, O(1) space | F12: Reverse whole, then reverse parts | G12: O(n) | H12: W02 | I12: =COUNTIFS('Problem Tracker'!$C:$C,"Array",'Problem Tracker'!$D:$D,"In-place Manipulation",'Problem Tracker'!$E:$E,"Rotation / Reversal Trick") -> 2 | J12: =COUNTIFS('Problem Tracker'!$C:$C,"Array",'Problem Tracker'!$D:$D,"In-place Manipulation",'Problem Tracker'!$E:$E,"Rotation / Reversal Trick",'Problem Tracker'!$H:$H,"Easy") -> 0 | K12: =COUNTIFS('Problem Tracker'!$C:$C,"Array",'Problem Tracker'!$D:$D,"In-place Manipulation",'Problem Tracker'!$E:$E,"Rotation / Reversal Trick",'Problem Tracker'!$H:$H,"Medium") -> 2 | L12: =COUNTIFS('Problem Tracker'!$C:$C,"Array",'Problem Tracker'!$D:$D,"In-place Manipulation",'Problem Tracker'!$E:$E,"Rotation / Reversal Trick",'Problem Tracker'!$H:$H,"Hard") -> 0 | M12: =COUNTIFS('Problem Tracker'!$C:$C,"Array",'Problem Tracker'!$D:$D,"In-place Manipulation",'Problem Tracker'!$E:$E,"Rotation / Reversal Trick",'Problem Tracker'!$M:$M,"Solved")+COUNTIFS('Problem Tracker'!$C:$C,"Array",'Problem Tracker'!$D:$D,"In-place Manipulation",'Problem Tracker'!$E:$E,"Rotation / Reversal Trick",'Problem Tracker'!$M:$M,"Mastered") -> 0 | N12: =IF(I12=0,0,M12/I12) -> 0
A13: Array | B13: In-place Manipulation | C13: Majority Vote (Boyer–Moore) | D13: High | E13: Element appearing > n/2 or > n/3 times, O(1) space | F13: Candidate + counter; verify in second pass | G13: O(n), O(1) | H13: W02 | I13: =COUNTIFS('Problem Tracker'!$C:$C,"Array",'Problem Tracker'!$D:$D,"In-place Manipulation",'Problem Tracker'!$E:$E,"Majority Vote (Boyer–Moore)") -> 2 | J13: =COUNTIFS('Problem Tracker'!$C:$C,"Array",'Problem Tracker'!$D:$D,"In-place Manipulation",'Problem Tracker'!$E:$E,"Majority Vote (Boyer–Moore)",'Problem Tracker'!$H:$H,"Easy") -> 1 | K13: =COUNTIFS('Problem Tracker'!$C:$C,"Array",'Problem Tracker'!$D:$D,"In-place Manipulation",'Problem Tracker'!$E:$E,"Majority Vote (Boyer–Moore)",'Problem Tracker'!$H:$H,"Medium") -> 1 | L13: =COUNTIFS('Problem Tracker'!$C:$C,"Array",'Problem Tracker'!$D:$D,"In-place Manipulation",'Problem Tracker'!$E:$E,"Majority Vote (Boyer–Moore)",'Problem Tracker'!$H:$H,"Hard") -> 0 | M13: =COUNTIFS('Problem Tracker'!$C:$C,"Array",'Problem Tracker'!$D:$D,"In-place Manipulation",'Problem Tracker'!$E:$E,"Majority Vote (Boyer–Moore)",'Problem Tracker'!$M:$M,"Solved")+COUNTIFS('Problem Tracker'!$C:$C,"Array",'Problem Tracker'!$D:$D,"In-place Manipulation",'Problem Tracker'!$E:$E,"Majority Vote (Boyer–Moore)",'Problem Tracker'!$M:$M,"Mastered") -> 0 | N13: =IF(I13=0,0,M13/I13) -> 0
A14: Array | B14: In-place Manipulation | C14: Cyclic Sort / Index Marking | D14: 🔥 Very High | E14: Numbers in range [1..n] or [0..n]; find missing/duplicate | F14: Place x at index x−1, or negate arr[x] to mark seen | G14: O(n), O(1) | H14: W02 | I14: =COUNTIFS('Problem Tracker'!$C:$C,"Array",'Problem Tracker'!$D:$D,"In-place Manipulation",'Problem Tracker'!$E:$E,"Cyclic Sort / Index Marking") -> 4 | J14: =COUNTIFS('Problem Tracker'!$C:$C,"Array",'Problem Tracker'!$D:$D,"In-place Manipulation",'Problem Tracker'!$E:$E,"Cyclic Sort / Index Marking",'Problem Tracker'!$H:$H,"Easy") -> 1 | K14: =COUNTIFS('Problem Tracker'!$C:$C,"Array",'Problem Tracker'!$D:$D,"In-place Manipulation",'Problem Tracker'!$E:$E,"Cyclic Sort / Index Marking",'Problem Tracker'!$H:$H,"Medium") -> 2 | L14: =COUNTIFS('Problem Tracker'!$C:$C,"Array",'Problem Tracker'!$D:$D,"In-place Manipulation",'Problem Tracker'!$E:$E,"Cyclic Sort / Index Marking",'Problem Tracker'!$H:$H,"Hard") -> 1 | M14: =COUNTIFS('Problem Tracker'!$C:$C,"Array",'Problem Tracker'!$D:$D,"In-place Manipulation",'Problem Tracker'!$E:$E,"Cyclic Sort / Index Marking",'Problem Tracker'!$M:$M,"Solved")+COUNTIFS('Problem Tracker'!$C:$C,"Array",'Problem Tracker'!$D:$D,"In-place Manipulation",'Problem Tracker'!$E:$E,"Cyclic Sort / Index Marking",'Problem Tracker'!$M:$M,"Mastered") -> 0 | N14: =IF(I14=0,0,M14/I14) -> 0
A15: Array | B15: Sliding Window | C15: Fixed Size | D15: 🔥 Very High | E15: 'Subarray/substring of size k', window length is given | F15: Add arr[r], remove arr[r−k]; update answer each step | G15: O(n) | H15: W03 | I15: =COUNTIFS('Problem Tracker'!$C:$C,"Array",'Problem Tracker'!$D:$D,"Sliding Window",'Problem Tracker'!$E:$E,"Fixed Size") -> 7 | J15: =COUNTIFS('Problem Tracker'!$C:$C,"Array",'Problem Tracker'!$D:$D,"Sliding Window",'Problem Tracker'!$E:$E,"Fixed Size",'Problem Tracker'!$H:$H,"Easy") -> 1 | K15: =COUNTIFS('Problem Tracker'!$C:$C,"Array",'Problem Tracker'!$D:$D,"Sliding Window",'Problem Tracker'!$E:$E,"Fixed Size",'Problem Tracker'!$H:$H,"Medium") -> 5 | L15: =COUNTIFS('Problem Tracker'!$C:$C,"Array",'Problem Tracker'!$D:$D,"Sliding Window",'Problem Tracker'!$E:$E,"Fixed Size",'Problem Tracker'!$H:$H,"Hard") -> 1 | M15: =COUNTIFS('Problem Tracker'!$C:$C,"Array",'Problem Tracker'!$D:$D,"Sliding Window",'Problem Tracker'!$E:$E,"Fixed Size",'Problem Tracker'!$M:$M,"Solved")+COUNTIFS('Problem Tracker'!$C:$C,"Array",'Problem Tracker'!$D:$D,"Sliding Window",'Problem Tracker'!$E:$E,"Fixed Size",'Problem Tracker'!$M:$M,"Mastered") -> 0 | N15: =IF(I15=0,0,M15/I15) -> 0
A16: Array | B16: Sliding Window | C16: Variable Size (Longest / Shortest Valid) | D16: 🔥 Very High | E16: 'Longest/shortest subarray such that…' with a monotone validity condition | F16: Expand r; while invalid shrink l; record best | G16: O(n) | H16: W03 | I16: =COUNTIFS('Problem Tracker'!$C:$C,"Array",'Problem Tracker'!$D:$D,"Sliding Window",'Problem Tracker'!$E:$E,"Variable Size (Longest / Shortest Valid)") -> 7 | J16: =COUNTIFS('Problem Tracker'!$C:$C,"Array",'Problem Tracker'!$D:$D,"Sliding Window",'Problem Tracker'!$E:$E,"Variable Size (Longest / Shortest Valid)",'Problem Tracker'!$H:$H,"Easy") -> 0 | K16: =COUNTIFS('Problem Tracker'!$C:$C,"Array",'Problem Tracker'!$D:$D,"Sliding Window",'Problem Tracker'!$E:$E,"Variable Size (Longest / Shortest Valid)",'Problem Tracker'!$H:$H,"Medium") -> 6 | L16: =COUNTIFS('Problem Tracker'!$C:$C,"Array",'Problem Tracker'!$D:$D,"Sliding Window",'Problem Tracker'!$E:$E,"Variable Size (Longest / Shortest Valid)",'Problem Tracker'!$H:$H,"Hard") -> 1 | M16: =COUNTIFS('Problem Tracker'!$C:$C,"Array",'Problem Tracker'!$D:$D,"Sliding Window",'Problem Tracker'!$E:$E,"Variable Size (Longest / Shortest Valid)",'Problem Tracker'!$M:$M,"Solved")+COUNTIFS('Problem Tracker'!$C:$C,"Array",'Problem Tracker'!$D:$D,"Sliding Window",'Problem Tracker'!$E:$E,"Variable Size (Longest / Shortest Valid)",'Problem Tracker'!$M:$M,"Mastered") -> 0 | N16: =IF(I16=0,0,M16/I16) -> 0
A17: Array | B17: Sliding Window | C17: Expand–Shrink Counting (At-Most-K Trick) | D17: High | E17: 'Count subarrays' with exactly K / at most K / product < K | F17: count(exactly K) = atMost(K) − atMost(K−1); add (r−l+1) per step | G17: O(n) | H17: W03 | I17: =COUNTIFS('Problem Tracker'!$C:$C,"Array",'Problem Tracker'!$D:$D,"Sliding Window",'Problem Tracker'!$E:$E,"Expand–Shrink Counting (At-Most-K Trick)") -> 7 | J17: =COUNTIFS('Problem Tracker'!$C:$C,"Array",'Problem Tracker'!$D:$D,"Sliding Window",'Problem Tracker'!$E:$E,"Expand–Shrink Counting (At-Most-K Trick)",'Problem Tracker'!$H:$H,"Easy") -> 0 | K17: =COUNTIFS('Problem Tracker'!$C:$C,"Array",'Problem Tracker'!$D:$D,"Sliding Window",'Problem Tracker'!$E:$E,"Expand–Shrink Counting (At-Most-K Trick)",'Problem Tracker'!$H:$H,"Medium") -> 5 | L17: =COUNTIFS('Problem Tracker'!$C:$C,"Array",'Problem Tracker'!$D:$D,"Sliding Window",'Problem Tracker'!$E:$E,"Expand–Shrink Counting (At-Most-K Trick)",'Problem Tracker'!$H:$H,"Hard") -> 2 | M17: =COUNTIFS('Problem Tracker'!$C:$C,"Array",'Problem Tracker'!$D:$D,"Sliding Window",'Problem Tracker'!$E:$E,"Expand–Shrink Counting (At-Most-K Trick)",'Problem Tracker'!$M:$M,"Solved")+COUNTIFS('Problem Tracker'!$C:$C,"Array",'Problem Tracker'!$D:$D,"Sliding Window",'Problem Tracker'!$E:$E,"Expand–Shrink Counting (At-Most-K Trick)",'Problem Tracker'!$M:$M,"Mastered") -> 0 | N17: =IF(I17=0,0,M17/I17) -> 0
A18: Array | B18: Sliding Window | C18: Monotonic Window (Deque) | D18: High | E18: Max/min of every window, or window with |max−min| ≤ limit | F18: Deque of indices kept increasing/decreasing; pop expired front | G18: O(n) | H18: W03 | I18: =COUNTIFS('Problem Tracker'!$C:$C,"Array",'Problem Tracker'!$D:$D,"Sliding Window",'Problem Tracker'!$E:$E,"Monotonic Window (Deque)") -> 5 | J18: =COUNTIFS('Problem Tracker'!$C:$C,"Array",'Problem Tracker'!$D:$D,"Sliding Window",'Problem Tracker'!$E:$E,"Monotonic Window (Deque)",'Problem Tracker'!$H:$H,"Easy") -> 0 | K18: =COUNTIFS('Problem Tracker'!$C:$C,"Array",'Problem Tracker'!$D:$D,"Sliding Window",'Problem Tracker'!$E:$E,"Monotonic Window (Deque)",'Problem Tracker'!$H:$H,"Medium") -> 2 | L18: =COUNTIFS('Problem Tracker'!$C:$C,"Array",'Problem Tracker'!$D:$D,"Sliding Window",'Problem Tracker'!$E:$E,"Monotonic Window (Deque)",'Problem Tracker'!$H:$H,"Hard") -> 3 | M18: =COUNTIFS('Problem Tracker'!$C:$C,"Array",'Problem Tracker'!$D:$D,"Sliding Window",'Problem Tracker'!$E:$E,"Monotonic Window (Deque)",'Problem Tracker'!$M:$M,"Solved")+COUNTIFS('Problem Tracker'!$C:$C,"Array",'Problem Tracker'!$D:$D,"Sliding Window",'Problem Tracker'!$E:$E,"Monotonic Window (Deque)",'Problem Tracker'!$M:$M,"Mastered") -> 0 | N18: =IF(I18=0,0,M18/I18) -> 0
A19: Array | B19: Prefix Sum | C19: 1D Prefix Sum | D19: 🔥 Very High | E19: Many range-sum queries, pivot/balance index | F19: pre[i+1] = pre[i] + a[i]; sum(l..r) = pre[r+1] − pre[l] | G19: O(n) build, O(1) query | H19: W03 | I19: =COUNTIFS('Problem Tracker'!$C:$C,"Array",'Problem Tracker'!$D:$D,"Prefix Sum",'Problem Tracker'!$E:$E,"1D Prefix Sum") -> 3 | J19: =COUNTIFS('Problem Tracker'!$C:$C,"Array",'Problem Tracker'!$D:$D,"Prefix Sum",'Problem Tracker'!$E:$E,"1D Prefix Sum",'Problem Tracker'!$H:$H,"Easy") -> 3 | K19: =COUNTIFS('Problem Tracker'!$C:$C,"Array",'Problem Tracker'!$D:$D,"Prefix Sum",'Problem Tracker'!$E:$E,"1D Prefix Sum",'Problem Tracker'!$H:$H,"Medium") -> 0 | L19: =COUNTIFS('Problem Tracker'!$C:$C,"Array",'Problem Tracker'!$D:$D,"Prefix Sum",'Problem Tracker'!$E:$E,"1D Prefix Sum",'Problem Tracker'!$H:$H,"Hard") -> 0 | M19: =COUNTIFS('Problem Tracker'!$C:$C,"Array",'Problem Tracker'!$D:$D,"Prefix Sum",'Problem Tracker'!$E:$E,"1D Prefix Sum",'Problem Tracker'!$M:$M,"Solved")+COUNTIFS('Problem Tracker'!$C:$C,"Array",'Problem Tracker'!$D:$D,"Prefix Sum",'Problem Tracker'!$E:$E,"1D Prefix Sum",'Problem Tracker'!$M:$M,"Mastered") -> 0 | N19: =IF(I19=0,0,M19/I19) -> 0
A20: Array | B20: Prefix Sum | C20: Prefix Sum + HashMap | D20: 🔥 Very High | E20: Count/longest subarray with sum = K, divisible by K, equal 0s & 1s (negatives allowed) | F20: Map prefix → count/first index; look up pre − K | G20: O(n) | H20: W03 | I20: =COUNTIFS('Problem Tracker'!$C:$C,"Array",'Problem Tracker'!$D:$D,"Prefix Sum",'Problem Tracker'!$E:$E,"Prefix Sum + HashMap") -> 5 | J20: =COUNTIFS('Problem Tracker'!$C:$C,"Array",'Problem Tracker'!$D:$D,"Prefix Sum",'Problem Tracker'!$E:$E,"Prefix Sum + HashMap",'Problem Tracker'!$H:$H,"Easy") -> 0 | K20: =COUNTIFS('Problem Tracker'!$C:$C,"Array",'Problem Tracker'!$D:$D,"Prefix Sum",'Problem Tracker'!$E:$E,"Prefix Sum + HashMap",'Problem Tracker'!$H:$H,"Medium") -> 4 | L20: =COUNTIFS('Problem Tracker'!$C:$C,"Array",'Problem Tracker'!$D:$D,"Prefix Sum",'Problem Tracker'!$E:$E,"Prefix Sum + HashMap",'Problem Tracker'!$H:$H,"Hard") -> 1 | M20: =COUNTIFS('Problem Tracker'!$C:$C,"Array",'Problem Tracker'!$D:$D,"Prefix Sum",'Problem Tracker'!$E:$E,"Prefix Sum + HashMap",'Problem Tracker'!$M:$M,"Solved")+COUNTIFS('Problem Tracker'!$C:$C,"Array",'Problem Tracker'!$D:$D,"Prefix Sum",'Problem Tracker'!$E:$E,"Prefix Sum + HashMap",'Problem Tracker'!$M:$M,"Mastered") -> 0 | N20: =IF(I20=0,0,M20/I20) -> 0
A21: Array | B21: Prefix Sum | C21: 2D Prefix Sum | D21: High | E21: Rectangle sum queries on a matrix | F21: P[i][j] = a + P[i−1][j] + P[i][j−1] − P[i−1][j−1] | G21: O(mn) build, O(1) query | H21: W03 | I21: =COUNTIFS('Problem Tracker'!$C:$C,"Array",'Problem Tracker'!$D:$D,"Prefix Sum",'Problem Tracker'!$E:$E,"2D Prefix Sum") -> 2 | J21: =COUNTIFS('Problem Tracker'!$C:$C,"Array",'Problem Tracker'!$D:$D,"Prefix Sum",'Problem Tracker'!$E:$E,"2D Prefix Sum",'Problem Tracker'!$H:$H,"Easy") -> 0 | K21: =COUNTIFS('Problem Tracker'!$C:$C,"Array",'Problem Tracker'!$D:$D,"Prefix Sum",'Problem Tracker'!$E:$E,"2D Prefix Sum",'Problem Tracker'!$H:$H,"Medium") -> 2 | L21: =COUNTIFS('Problem Tracker'!$C:$C,"Array",'Problem Tracker'!$D:$D,"Prefix Sum",'Problem Tracker'!$E:$E,"2D Prefix Sum",'Problem Tracker'!$H:$H,"Hard") -> 0 | M21: =COUNTIFS('Problem Tracker'!$C:$C,"Array",'Problem Tracker'!$D:$D,"Prefix Sum",'Problem Tracker'!$E:$E,"2D Prefix Sum",'Problem Tracker'!$M:$M,"Solved")+COUNTIFS('Problem Tracker'!$C:$C,"Array",'Problem Tracker'!$D:$D,"Prefix Sum",'Problem Tracker'!$E:$E,"2D Prefix Sum",'Problem Tracker'!$M:$M,"Mastered") -> 0 | N21: =IF(I21=0,0,M21/I21) -> 0
A22: Array | B22: Prefix Sum | C22: Difference Array | D22: High | E22: Many range-update operations, then read final array | F22: diff[l] += v; diff[r+1] −= v; prefix-sum at the end | G22: O(n + q) | H22: W03 | I22: =COUNTIFS('Problem Tracker'!$C:$C,"Array",'Problem Tracker'!$D:$D,"Prefix Sum",'Problem Tracker'!$E:$E,"Difference Array") -> 3 | J22: =COUNTIFS('Problem Tracker'!$C:$C,"Array",'Problem Tracker'!$D:$D,"Prefix Sum",'Problem Tracker'!$E:$E,"Difference Array",'Problem Tracker'!$H:$H,"Easy") -> 0 | K22: =COUNTIFS('Problem Tracker'!$C:$C,"Array",'Problem Tracker'!$D:$D,"Prefix Sum",'Problem Tracker'!$E:$E,"Difference Array",'Problem Tracker'!$H:$H,"Medium") -> 3 | L22: =COUNTIFS('Problem Tracker'!$C:$C,"Array",'Problem Tracker'!$D:$D,"Prefix Sum",'Problem Tracker'!$E:$E,"Difference Array",'Problem Tracker'!$H:$H,"Hard") -> 0 | M22: =COUNTIFS('Problem Tracker'!$C:$C,"Array",'Problem Tracker'!$D:$D,"Prefix Sum",'Problem Tracker'!$E:$E,"Difference Array",'Problem Tracker'!$M:$M,"Solved")+COUNTIFS('Problem Tracker'!$C:$C,"Array",'Problem Tracker'!$D:$D,"Prefix Sum",'Problem Tracker'!$E:$E,"Difference Array",'Problem Tracker'!$M:$M,"Mastered") -> 0 | N22: =IF(I22=0,0,M22/I22) -> 0
A23: Array | B23: Prefix Sum | C23: Prefix–Suffix Products / Splits | D23: 🔥 Very High | E23: Answer for i depends on everything left and right of i | F23: Build left pass and right pass arrays (or one running var) | G23: O(n) | H23: W03 | I23: =COUNTIFS('Problem Tracker'!$C:$C,"Array",'Problem Tracker'!$D:$D,"Prefix Sum",'Problem Tracker'!$E:$E,"Prefix–Suffix Products / Splits") -> 2 | J23: =COUNTIFS('Problem Tracker'!$C:$C,"Array",'Problem Tracker'!$D:$D,"Prefix Sum",'Problem Tracker'!$E:$E,"Prefix–Suffix Products / Splits",'Problem Tracker'!$H:$H,"Easy") -> 0 | K23: =COUNTIFS('Problem Tracker'!$C:$C,"Array",'Problem Tracker'!$D:$D,"Prefix Sum",'Problem Tracker'!$E:$E,"Prefix–Suffix Products / Splits",'Problem Tracker'!$H:$H,"Medium") -> 2 | L23: =COUNTIFS('Problem Tracker'!$C:$C,"Array",'Problem Tracker'!$D:$D,"Prefix Sum",'Problem Tracker'!$E:$E,"Prefix–Suffix Products / Splits",'Problem Tracker'!$H:$H,"Hard") -> 0 | M23: =COUNTIFS('Problem Tracker'!$C:$C,"Array",'Problem Tracker'!$D:$D,"Prefix Sum",'Problem Tracker'!$E:$E,"Prefix–Suffix Products / Splits",'Problem Tracker'!$M:$M,"Solved")+COUNTIFS('Problem Tracker'!$C:$C,"Array",'Problem Tracker'!$D:$D,"Prefix Sum",'Problem Tracker'!$E:$E,"Prefix–Suffix Products / Splits",'Problem Tracker'!$M:$M,"Mastered") -> 0 | N23: =IF(I23=0,0,M23/I23) -> 0
A24: Array | B24: Kadane's / Subarray | C24: Running Min / Max (Kadane Core) | D24: 🔥 Very High | E24: Max profit / max contiguous sum in one pass | F24: cur = max(x, cur + x); best = max(best, cur) | G24: O(n), O(1) | H24: W03 | I24: =COUNTIFS('Problem Tracker'!$C:$C,"Array",'Problem Tracker'!$D:$D,"Kadane's / Subarray",'Problem Tracker'!$E:$E,"Running Min / Max (Kadane Core)") -> 3 | J24: =COUNTIFS('Problem Tracker'!$C:$C,"Array",'Problem Tracker'!$D:$D,"Kadane's / Subarray",'Problem Tracker'!$E:$E,"Running Min / Max (Kadane Core)",'Problem Tracker'!$H:$H,"Easy") -> 1 | K24: =COUNTIFS('Problem Tracker'!$C:$C,"Array",'Problem Tracker'!$D:$D,"Kadane's / Subarray",'Problem Tracker'!$E:$E,"Running Min / Max (Kadane Core)",'Problem Tracker'!$H:$H,"Medium") -> 2 | L24: =COUNTIFS('Problem Tracker'!$C:$C,"Array",'Problem Tracker'!$D:$D,"Kadane's / Subarray",'Problem Tracker'!$E:$E,"Running Min / Max (Kadane Core)",'Problem Tracker'!$H:$H,"Hard") -> 0 | M24: =COUNTIFS('Problem Tracker'!$C:$C,"Array",'Problem Tracker'!$D:$D,"Kadane's / Subarray",'Problem Tracker'!$E:$E,"Running Min / Max (Kadane Core)",'Problem Tracker'!$M:$M,"Solved")+COUNTIFS('Problem Tracker'!$C:$C,"Array",'Problem Tracker'!$D:$D,"Kadane's / Subarray",'Problem Tracker'!$E:$E,"Running Min / Max (Kadane Core)",'Problem Tracker'!$M:$M,"Mastered") -> 0 | N24: =IF(I24=0,0,M24/I24) -> 0
A25: Array | B25: Kadane's / Subarray | C25: Kadane Variants (Product / Circular / Deletion) | D25: High | E25: Negatives flip sign, wrap-around, one skip allowed | F25: Track both max & min; total − minSubarray for circular | G25: O(n) | H25: W03 | I25: =COUNTIFS('Problem Tracker'!$C:$C,"Array",'Problem Tracker'!$D:$D,"Kadane's / Subarray",'Problem Tracker'!$E:$E,"Kadane Variants (Product / Circular / Deletion)") -> 3 | J25: =COUNTIFS('Problem Tracker'!$C:$C,"Array",'Problem Tracker'!$D:$D,"Kadane's / Subarray",'Problem Tracker'!$E:$E,"Kadane Variants (Product / Circular / Deletion)",'Problem Tracker'!$H:$H,"Easy") -> 0 | K25: =COUNTIFS('Problem Tracker'!$C:$C,"Array",'Problem Tracker'!$D:$D,"Kadane's / Subarray",'Problem Tracker'!$E:$E,"Kadane Variants (Product / Circular / Deletion)",'Problem Tracker'!$H:$H,"Medium") -> 3 | L25: =COUNTIFS('Problem Tracker'!$C:$C,"Array",'Problem Tracker'!$D:$D,"Kadane's / Subarray",'Problem Tracker'!$E:$E,"Kadane Variants (Product / Circular / Deletion)",'Problem Tracker'!$H:$H,"Hard") -> 0 | M25: =COUNTIFS('Problem Tracker'!$C:$C,"Array",'Problem Tracker'!$D:$D,"Kadane's / Subarray",'Problem Tracker'!$E:$E,"Kadane Variants (Product / Circular / Deletion)",'Problem Tracker'!$M:$M,"Solved")+COUNTIFS('Problem Tracker'!$C:$C,"Array",'Problem Tracker'!$D:$D,"Kadane's / Subarray",'Problem Tracker'!$E:$E,"Kadane Variants (Product / Circular / Deletion)",'Problem Tracker'!$M:$M,"Mastered") -> 0 | N25: =IF(I25=0,0,M25/I25) -> 0
A26: ▌ STRING | I26: =COUNTIF('Problem Tracker'!$C:$C,"String") -> 34 | M26: =COUNTIFS('Problem Tracker'!$C:$C,"String",'Problem Tracker'!$M:$M,"Solved")+COUNTIFS('Problem Tracker'!$C:$C,"String",'Problem Tracker'!$M:$M,"Mastered") -> 0 | N26: =IF(I26=0,0,M26/I26) -> 0
A27: String | B27: Palindrome | C27: Two-Pointer Check | D27: High | E27: Is it (almost) a palindrome? | F27: Compare ends; on mismatch try skipping one side | G27: O(n) | H27: W03 | I27: =COUNTIFS('Problem Tracker'!$C:$C,"String",'Problem Tracker'!$D:$D,"Palindrome",'Problem Tracker'!$E:$E,"Two-Pointer Check") -> 2 | J27: =COUNTIFS('Problem Tracker'!$C:$C,"String",'Problem Tracker'!$D:$D,"Palindrome",'Problem Tracker'!$E:$E,"Two-Pointer Check",'Problem Tracker'!$H:$H,"Easy") -> 2 | K27: =COUNTIFS('Problem Tracker'!$C:$C,"String",'Problem Tracker'!$D:$D,"Palindrome",'Problem Tracker'!$E:$E,"Two-Pointer Check",'Problem Tracker'!$H:$H,"Medium") -> 0 | L27: =COUNTIFS('Problem Tracker'!$C:$C,"String",'Problem Tracker'!$D:$D,"Palindrome",'Problem Tracker'!$E:$E,"Two-Pointer Check",'Problem Tracker'!$H:$H,"Hard") -> 0 | M27: =COUNTIFS('Problem Tracker'!$C:$C,"String",'Problem Tracker'!$D:$D,"Palindrome",'Problem Tracker'!$E:$E,"Two-Pointer Check",'Problem Tracker'!$M:$M,"Solved")+COUNTIFS('Problem Tracker'!$C:$C,"String",'Problem Tracker'!$D:$D,"Palindrome",'Problem Tracker'!$E:$E,"Two-Pointer Check",'Problem Tracker'!$M:$M,"Mastered") -> 0 | N27: =IF(I27=0,0,M27/I27) -> 0
A28: String | B28: Palindrome | C28: Expand Around Center | D28: 🔥 Very High | E28: Longest / count of palindromic substrings | F28: For each of 2n−1 centres expand while s[l]==s[r] | G28: O(n²) | H28: W03 | I28: =COUNTIFS('Problem Tracker'!$C:$C,"String",'Problem Tracker'!$D:$D,"Palindrome",'Problem Tracker'!$E:$E,"Expand Around Center") -> 2 | J28: =COUNTIFS('Problem Tracker'!$C:$C,"String",'Problem Tracker'!$D:$D,"Palindrome",'Problem Tracker'!$E:$E,"Expand Around Center",'Problem Tracker'!$H:$H,"Easy") -> 0 | K28: =COUNTIFS('Problem Tracker'!$C:$C,"String",'Problem Tracker'!$D:$D,"Palindrome",'Problem Tracker'!$E:$E,"Expand Around Center",'Problem Tracker'!$H:$H,"Medium") -> 2 | L28: =COUNTIFS('Problem Tracker'!$C:$C,"String",'Problem Tracker'!$D:$D,"Palindrome",'Problem Tracker'!$E:$E,"Expand Around Center",'Problem Tracker'!$H:$H,"Hard") -> 0 | M28: =COUNTIFS('Problem Tracker'!$C:$C,"String",'Problem Tracker'!$D:$D,"Palindrome",'Problem Tracker'!$E:$E,"Expand Around Center",'Problem Tracker'!$M:$M,"Solved")+COUNTIFS('Problem Tracker'!$C:$C,"String",'Problem Tracker'!$D:$D,"Palindrome",'Problem Tracker'!$E:$E,"Expand Around Center",'Problem Tracker'!$M:$M,"Mastered") -> 0 | N28: =IF(I28=0,0,M28/I28) -> 0
A29: String | B29: Palindrome | C29: Palindrome Construction | D29: Medium | E29: Build longest palindrome / make string palindrome by adding chars | F29: Character parity counts, or KMP on s + '#' + rev(s) | G29: O(n) | H29: W03 | I29: =COUNTIFS('Problem Tracker'!$C:$C,"String",'Problem Tracker'!$D:$D,"Palindrome",'Problem Tracker'!$E:$E,"Palindrome Construction") -> 3 | J29: =COUNTIFS('Problem Tracker'!$C:$C,"String",'Problem Tracker'!$D:$D,"Palindrome",'Problem Tracker'!$E:$E,"Palindrome Construction",'Problem Tracker'!$H:$H,"Easy") -> 1 | K29: =COUNTIFS('Problem Tracker'!$C:$C,"String",'Problem Tracker'!$D:$D,"Palindrome",'Problem Tracker'!$E:$E,"Palindrome Construction",'Problem Tracker'!$H:$H,"Medium") -> 0 | L29: =COUNTIFS('Problem Tracker'!$C:$C,"String",'Problem Tracker'!$D:$D,"Palindrome",'Problem Tracker'!$E:$E,"Palindrome Construction",'Problem Tracker'!$H:$H,"Hard") -> 2 | M29: =COUNTIFS('Problem Tracker'!$C:$C,"String",'Problem Tracker'!$D:$D,"Palindrome",'Problem Tracker'!$E:$E,"Palindrome Construction",'Problem Tracker'!$M:$M,"Solved")+COUNTIFS('Problem Tracker'!$C:$C,"String",'Problem Tracker'!$D:$D,"Palindrome",'Problem Tracker'!$E:$E,"Palindrome Construction",'Problem Tracker'!$M:$M,"Mastered") -> 0 | N29: =IF(I29=0,0,M29/I29) -> 0
A30: String | B30: Anagram / Frequency | C30: Character Count Comparison | D30: 🔥 Very High | E30: Anagram, ransom note, 'same characters', first unique | F30: int[26] counts; compare or decrement | G30: O(n) | H30: W03 | I30: =COUNTIFS('Problem Tracker'!$C:$C,"String",'Problem Tracker'!$D:$D,"Anagram / Frequency",'Problem Tracker'!$E:$E,"Character Count Comparison") -> 6 | J30: =COUNTIFS('Problem Tracker'!$C:$C,"String",'Problem Tracker'!$D:$D,"Anagram / Frequency",'Problem Tracker'!$E:$E,"Character Count Comparison",'Problem Tracker'!$H:$H,"Easy") -> 3 | K30: =COUNTIFS('Problem Tracker'!$C:$C,"String",'Problem Tracker'!$D:$D,"Anagram / Frequency",'Problem Tracker'!$E:$E,"Character Count Comparison",'Problem Tracker'!$H:$H,"Medium") -> 3 | L30: =COUNTIFS('Problem Tracker'!$C:$C,"String",'Problem Tracker'!$D:$D,"Anagram / Frequency",'Problem Tracker'!$E:$E,"Character Count Comparison",'Problem Tracker'!$H:$H,"Hard") -> 0 | M30: =COUNTIFS('Problem Tracker'!$C:$C,"String",'Problem Tracker'!$D:$D,"Anagram / Frequency",'Problem Tracker'!$E:$E,"Character Count Comparison",'Problem Tracker'!$M:$M,"Solved")+COUNTIFS('Problem Tracker'!$C:$C,"String",'Problem Tracker'!$D:$D,"Anagram / Frequency",'Problem Tracker'!$E:$E,"Character Count Comparison",'Problem Tracker'!$M:$M,"Mastered") -> 0 | N30: =IF(I30=0,0,M30/I30) -> 0
A31: String | B31: Anagram / Frequency | C31: Bijection / Mapping | D31: Medium | E31: Isomorphic strings, word pattern, one-to-one mapping | F31: Two maps (a→b and b→a) or compare first-seen indices | G31: O(n) | H31: W03 | I31: =COUNTIFS('Problem Tracker'!$C:$C,"String",'Problem Tracker'!$D:$D,"Anagram / Frequency",'Problem Tracker'!$E:$E,"Bijection / Mapping") -> 3 | J31: =COUNTIFS('Problem Tracker'!$C:$C,"String",'Problem Tracker'!$D:$D,"Anagram / Frequency",'Problem Tracker'!$E:$E,"Bijection / Mapping",'Problem Tracker'!$H:$H,"Easy") -> 2 | K31: =COUNTIFS('Problem Tracker'!$C:$C,"String",'Problem Tracker'!$D:$D,"Anagram / Frequency",'Problem Tracker'!$E:$E,"Bijection / Mapping",'Problem Tracker'!$H:$H,"Medium") -> 1 | L31: =COUNTIFS('Problem Tracker'!$C:$C,"String",'Problem Tracker'!$D:$D,"Anagram / Frequency",'Problem Tracker'!$E:$E,"Bijection / Mapping",'Problem Tracker'!$H:$H,"Hard") -> 0 | M31: =COUNTIFS('Problem Tracker'!$C:$C,"String",'Problem Tracker'!$D:$D,"Anagram / Frequency",'Problem Tracker'!$E:$E,"Bijection / Mapping",'Problem Tracker'!$M:$M,"Solved")+COUNTIFS('Problem Tracker'!$C:$C,"String",'Problem Tracker'!$D:$D,"Anagram / Frequency",'Problem Tracker'!$E:$E,"Bijection / Mapping",'Problem Tracker'!$M:$M,"Mastered") -> 0 | N31: =IF(I31=0,0,M31/I31) -> 0
A32: String | B32: Pattern Matching | C32: KMP (Prefix Function) | D32: High | E32: Find pattern in text in linear time; longest prefix = suffix | F32: Build LPS array; never move text pointer back | G32: O(n + m) | H32: W03 | I32: =COUNTIFS('Problem Tracker'!$C:$C,"String",'Problem Tracker'!$D:$D,"Pattern Matching",'Problem Tracker'!$E:$E,"KMP (Prefix Function)") -> 3 | J32: =COUNTIFS('Problem Tracker'!$C:$C,"String",'Problem Tracker'!$D:$D,"Pattern Matching",'Problem Tracker'!$E:$E,"KMP (Prefix Function)",'Problem Tracker'!$H:$H,"Easy") -> 2 | K32: =COUNTIFS('Problem Tracker'!$C:$C,"String",'Problem Tracker'!$D:$D,"Pattern Matching",'Problem Tracker'!$E:$E,"KMP (Prefix Function)",'Problem Tracker'!$H:$H,"Medium") -> 0 | L32: =COUNTIFS('Problem Tracker'!$C:$C,"String",'Problem Tracker'!$D:$D,"Pattern Matching",'Problem Tracker'!$E:$E,"KMP (Prefix Function)",'Problem Tracker'!$H:$H,"Hard") -> 1 | M32: =COUNTIFS('Problem Tracker'!$C:$C,"String",'Problem Tracker'!$D:$D,"Pattern Matching",'Problem Tracker'!$E:$E,"KMP (Prefix Function)",'Problem Tracker'!$M:$M,"Solved")+COUNTIFS('Problem Tracker'!$C:$C,"String",'Problem Tracker'!$D:$D,"Pattern Matching",'Problem Tracker'!$E:$E,"KMP (Prefix Function)",'Problem Tracker'!$M:$M,"Mastered") -> 0 | N32: =IF(I32=0,0,M32/I32) -> 0
A33: String | B33: Pattern Matching | C33: Rabin–Karp / Rolling Hash | D33: Medium | E33: Repeated / duplicate substrings of length L | F33: Polynomial rolling hash; binary search on L if needed | G33: O(n) avg | H33: W03 | I33: =COUNTIFS('Problem Tracker'!$C:$C,"String",'Problem Tracker'!$D:$D,"Pattern Matching",'Problem Tracker'!$E:$E,"Rabin–Karp / Rolling Hash") -> 3 | J33: =COUNTIFS('Problem Tracker'!$C:$C,"String",'Problem Tracker'!$D:$D,"Pattern Matching",'Problem Tracker'!$E:$E,"Rabin–Karp / Rolling Hash",'Problem Tracker'!$H:$H,"Easy") -> 0 | K33: =COUNTIFS('Problem Tracker'!$C:$C,"String",'Problem Tracker'!$D:$D,"Pattern Matching",'Problem Tracker'!$E:$E,"Rabin–Karp / Rolling Hash",'Problem Tracker'!$H:$H,"Medium") -> 2 | L33: =COUNTIFS('Problem Tracker'!$C:$C,"String",'Problem Tracker'!$D:$D,"Pattern Matching",'Problem Tracker'!$E:$E,"Rabin–Karp / Rolling Hash",'Problem Tracker'!$H:$H,"Hard") -> 1 | M33: =COUNTIFS('Problem Tracker'!$C:$C,"String",'Problem Tracker'!$D:$D,"Pattern Matching",'Problem Tracker'!$E:$E,"Rabin–Karp / Rolling Hash",'Problem Tracker'!$M:$M,"Solved")+COUNTIFS('Problem Tracker'!$C:$C,"String",'Problem Tracker'!$D:$D,"Pattern Matching",'Problem Tracker'!$E:$E,"Rabin–Karp / Rolling Hash",'Problem Tracker'!$M:$M,"Mastered") -> 0 | N33: =IF(I33=0,0,M33/I33) -> 0
A34: String | B34: Pattern Matching | C34: Z-Algorithm | D34: Medium | E34: Match of every suffix with prefix | F34: Z-array with [l, r] box | G34: O(n) | H34: W03 | I34: =COUNTIFS('Problem Tracker'!$C:$C,"String",'Problem Tracker'!$D:$D,"Pattern Matching",'Problem Tracker'!$E:$E,"Z-Algorithm") -> 1 | J34: =COUNTIFS('Problem Tracker'!$C:$C,"String",'Problem Tracker'!$D:$D,"Pattern Matching",'Problem Tracker'!$E:$E,"Z-Algorithm",'Problem Tracker'!$H:$H,"Easy") -> 0 | K34: =COUNTIFS('Problem Tracker'!$C:$C,"String",'Problem Tracker'!$D:$D,"Pattern Matching",'Problem Tracker'!$E:$E,"Z-Algorithm",'Problem Tracker'!$H:$H,"Medium") -> 0 | L34: =COUNTIFS('Problem Tracker'!$C:$C,"String",'Problem Tracker'!$D:$D,"Pattern Matching",'Problem Tracker'!$E:$E,"Z-Algorithm",'Problem Tracker'!$H:$H,"Hard") -> 1 | M34: =COUNTIFS('Problem Tracker'!$C:$C,"String",'Problem Tracker'!$D:$D,"Pattern Matching",'Problem Tracker'!$E:$E,"Z-Algorithm",'Problem Tracker'!$M:$M,"Solved")+COUNTIFS('Problem Tracker'!$C:$C,"String",'Problem Tracker'!$D:$D,"Pattern Matching",'Problem Tracker'!$E:$E,"Z-Algorithm",'Problem Tracker'!$M:$M,"Mastered") -> 0 | N34: =IF(I34=0,0,M34/I34) -> 0
